<?xml version="1.0" encoding="utf-8"?>
<!-- =================================================================================== -->
<!-- |    This document was autogenerated by xacro from urdf/spotmicroai.urdf.xacro    | -->
<!-- |    EDITING THIS FILE BY HAND IS NOT RECOMMENDED                                 | -->
<!-- =================================================================================== -->
<robot name="SpotMicroAI">
  <material name="yellow">
    <color rgba="0.92 0.83 0.0 1"/>
  </material>
  <material name="black">
    <color rgba="0.1 0.1 0.1 1"/>
  </material>
  <material name="grey">
    <color rgba="0.6 0.6 0.6 1"/>
  </material>
  <material name="blue">
    <color rgba="0.0 0.0 1.0 1"/>
  </material>
  <!-- Params -->
  <!-- Macros -->
  <!-- Robot Body -->
  <link name="base_link">
    <visual>
      <geometry>
        <mesh filename="package://spotmicro_cpp_pkg/mesh/body_frame.STL" scale="0.001 0.001 0.001"/>
      </geometry>
      <material name="black"/>
      <origin rpy="1.571 0 -1.571" xyz="0.1214 0.056 -0.035"/>
    </visual>
    <collision>
      <geometry>
        <box size="0.14 0.114 0.08"/>
      </geometry>
      <origin rpy="0 0 0" xyz="0 0 -0.0025"/>
    </collision>
    <inertial>
      <mass value="1.23"/>
      <origin xyz="0.01228 0.0046 -0.01105 " rpy="0.0 0.0 0.0"/>
      <inertia ixx="0.00126" ixy="0.000312" ixz="-0.000248" iyy="0.00324" iyz="-0.0000715" izz="0.00369"/>
    </inertial>
  </link>

  <link name="imu_link">
    <visual>
      <geometry>
        <box size="0.016 0.026 0.003"/>
      </geometry>
      <material name="blue"/>
      <origin rpy="0 0 0" xyz="0.0 0.0 0.0"/>
    </visual>
    <inertial>
      <origin xyz="0 0 0" rpy="0 0 0"/>
      <mass value="0.01"/>
      <inertia ixx="1.5e-6" ixy="0" ixz="0" iyy="1.5e-6" iyz="0" izz="1.5e-6"/>
    </inertial>
  </link>
  <joint name="base_imu" type="fixed">
    <parent link = "base_link"/>
    <child link = "imu_link"/>
    <origin rpy="0 1.571 0" xyz = "0 0 0.028"/>
  </joint>

  <link name="bottom_hs_sr04_link">
    <visual>
      <geometry>
        <mesh filename="package://spotmicro_cpp_pkg/mesh/HC_SR04.STL" scale="0.001 0.001 0.001"/>
      </geometry>
      <material name="grey"/>
      <origin rpy="0 1.571 0" xyz="-0.01717 -0.013 0.0213"/>
    </visual>
    <inertial>
      <mass value="0.03"/>
      <origin xyz="0 0 0" rpy="0 0 0"/>
      <inertia ixx="0.0001" ixy="0" ixz="0" iyy="0.0001" iyz="0" izz="0.0001"/>
    </inertial>
  </link>
  <joint name="base_hs_sr04" type="fixed">
    <parent link = "base_link"/>
    <child link="bottom_hs_sr04_link"/>
    <origin rpy="0 1.571 0" xyz = "-0.0185 -0.0016 -0.042"/>
  </joint>
  <!-- Lidar Backpack -->
  <!-- <link name="lidar_link">
    <visual>
      <geometry>
        <mesh filename="package://spotmicro_cpp_pkg/meshes/rplidar_main.STL" scale="0.001 0.001 0.001"/>
      </geometry>
      <material name="black"/>
      <origin rpy="1.57075 0 0" xyz="-0.06425 0.02885 0"/>
    </visual>
    <collision>
      <geometry>
        <box size="0.0985 0.0577 0.07"/>
      </geometry>
      <origin rpy="0 0 0" xyz="0 0 0"/>
    </collision>
    <inertial>
      <mass value="0.50"/>
      <inertia ixx="100" ixy="0" ixz="0" iyy="100" iyz="0" izz="100"/>
    </inertial>
  </link>
  <joint name="base_lidar" type="fixed">
    <parent link="base_link"/>
    <child link="lidar_link"/>
    <origin xyz="0 0 0.035"/>
  </joint> -->

  <link name="rear_link">
    <visual>
      <geometry>
        <mesh filename="package://spotmicro_cpp_pkg/mesh/bottom_rear.STL" scale="0.001 0.001 0.001"/>
      </geometry>
      <origin rpy="1.571 0 1.571" xyz="-0.093 -0.064 -0.04499"/>
      <material name="yellow"/>
    </visual>
    <collision>
      <geometry>
        <box size="0.06 0.11 0.07"/>
      </geometry>
      <origin rpy="0 0 0" xyz="0.145 0 0"/>
    </collision>
    <inertial>
      <mass value="0.16"/>
      <origin rpy="0 0 0" xyz="-0.00002 0.03963 0.03773"/>
      <inertia ixx="0.00153" ixy="0" ixz="0" iyy="0.00134" iyz="0.000283" izz="0.000611"/>
    </inertial>
  </link>
  <joint name="base_rear" type="fixed">
    <parent link="base_link"/>
    <child link="rear_link"/>
  </joint>

  <link name="front_link">
    <visual>
      <geometry>
        <mesh filename="package://spotmicro_cpp_pkg/mesh/F_cover.stl" scale="0.001 0.001 0.001"/>
      </geometry>
      <origin rpy="0 0 0" xyz="-0.128 0 0"/>
      <material name="yellow"/>
    </visual>
    <collision>
      <geometry>
        <box size="0.058 0.11 0.07"/>
      </geometry>
      <origin rpy="0 0 0" xyz="-0.145 0 0"/>
    </collision>
    <inertial>
      <mass value="0.5"/>
      <origin xyz="0.00005 0.04624 0.14229" rpy="0.0 0.0 0.0"/>
      <inertia ixx="0.000337" ixy="0" ixz="0" iyy="0.000944" iyz="0.000281" izz="0.00016833347"/>
    </inertial>
  </link>
  <joint name="base_front" type="fixed">
    <parent link="base_link"/>
    <child link="front_link"/>
  </joint>

  <!-- create Legs -->
  <link name="front_left_shoulder_link">
    <visual>
      <geometry>
        <mesh filename="package://spotmicro_cpp_pkg/mesh/LF_RB_shoulder.STL" scale="0.001 0.001 0.001"/>
      </geometry>
      <origin rpy="1.5701 0 0" xyz="-0.03 0.0105 -0.03825"/>
      <material name="black"/>
    </visual>
    <collision>
      <geometry>
        <box size="0.044 0.038 0.07"/>
      </geometry>
      <origin rpy="0 0 0" xyz="0 0 -0.0095"/>
    </collision>
    <inertial>
      <mass value="0.071"/>
      <inertia ixx="0.0000226" ixy="0" ixz="0" iyy="0.0000178" iyz="0" izz="0.0000238"/>
    </inertial>
  </link>
  <link name="front_left_leg_link_cover">
    <visual>
      <geometry>
        <mesh filename="package://spotmicro_cpp_pkg/mesh/L_arm_cover.STL" scale="0.001 0.001 0.001"/>
      </geometry>
      <origin rpy="0 3.142 0" xyz="0.018 -0.0287 0.025"/>
      <material name="yellow"/>
    </visual>
  </link>
  <link name="front_left_leg_link">
    <visual>
      <geometry>
        <mesh filename="package://spotmicro_cpp_pkg/mesh/L_arm.STL" scale="0.001 0.001 0.001"/>
      </geometry>
      <origin rpy="0 3.142 3.142" xyz="-0.02625 0.036 0.13809"/>
      <material name="black"/>
      <!--        <geometry>
          <box size="0.028 0.036 ${leg_length}"/>
        </geometry>
        <origin rpy="0.0 0.0 0.0" xyz="0.0 0.0 -0.050"/>
        <material name="yellow"/>-->
    </visual>
    <collision>
      <origin rpy="0.0 0.0 0.0" xyz="0.0 0.0 -0.035"/>
      <geometry>
        <box size="0.028 0.036 0.12"/>
      </geometry>
    </collision>
    <inertial>
      <mass value="0.124"/>
      <origin xyz="-0.003 0.001 -0.0407" rpy="0.0 0.0 0.0"/>
      <inertia ixx="0.000396" ixy="0" ixz="0.0000184" iyy="0.000038" iyz="-0.000003" izz="0.0000329"/>
    </inertial>
  </link>
  <link name="front_left_foot_link">
    <visual>
      <geometry>
        <mesh filename="package://spotmicro_cpp_pkg/mesh/Left_writs.STL" scale="0.001 0.001 0.001"/>
      </geometry>
      <origin rpy="0 0 -1.571" xyz="-0.014 0.0277 -0.2048"/>
      <material name="black"/>
    </visual>
    <collision>
      <geometry>
        <box size="0.026 0.020 0.115"/>
      </geometry>
      <origin rpy="0.0 0.0 0.0" xyz="0.0 0.0 -0.050"/>
    </collision>
    <inertial>
      <mass value="0.0657"/>
      <origin xyz="0.00066 0.00011 -0.0292" rpy="0.0 0.0 0.0"/>
      <inertia ixx="0.000164" ixy="0" ixz="0" iyy="0.000161" iyz="0" izz="0.0000107"/>
    </inertial>
  </link>
  <link name="front_left_toe_link">
    <visual>
      <geometry>
        <mesh filename="package://spotmicro_cpp_pkg/meshes/foot.stl" scale="0.001 0.001 0.001"/>
      </geometry>
      <origin rpy="0 -0.40010 0" xyz="0.001 -0.0105 0"/>
      <material name="grey"/>
    </visual>
    <collision>
      <geometry>
        <sphere radius="0.02"/>
      </geometry>
      <origin rpy="0 0 0" xyz="0 0 0"/>
      <contact_coefficients mu="1.1"/>
    </collision>
    <inertial>
      <mass value="0.05"/>
      <inertia ixx="1000" ixy="0" ixz="0" iyy="1000" iyz="0" izz="1000"/>
    </inertial>
  </link>


  <joint name="front_left_shoulder" type="revolute">
    <parent link="base_link"/>
    <child link="front_left_shoulder_link"/>
    <axis xyz="1 0 0"/>
    <origin rpy="0 0 0" xyz="-0.09165 -0.039 0.009"/>
    <limit effort="1000.0" lower="-0.872" upper="0.698" velocity="0.7"/>
    <dynamics damping="0.0" friction="0.5"/>
  </joint>
  <joint name="front_left_leg" type="revolute">
    <parent link="front_left_shoulder_link"/>
    <child link="front_left_leg_link"/>
    <axis xyz="0 1 0"/>
    <origin rpy="0 0 0" xyz="0 -0.0597 -0.01"/>
    <limit effort="1000.0" lower="-1.570" upper="1.570" velocity="0.5"/>
    <dynamics damping="0.0" friction="0.0"/>
  </joint>
  <joint name="front_left_leg_cover_joint" type="fixed">
    <parent link="front_left_leg_link"/>
    <child link="front_left_leg_link_cover"/>
    <origin xyz="0 0 0"/>
  </joint>
  <joint name="front_left_foot" type="revolute">
    <parent link="front_left_leg_link"/>
    <child link="front_left_foot_link"/>
    <axis xyz="0 1 0"/>
    <origin rpy="0 0 0" xyz="-0.01475 0 -0.10699"/>
    <limit effort="1000.0" lower="-0.174" upper="2.268" velocity="0.5"/>
    <dynamics damping="0.0" friction="0.5"/>
  </joint>
  <joint name="front_left_toe" type="fixed">
    <parent link="front_left_foot_link"/>
    <child link="front_left_toe_link"/>
    <origin xyz="0 0 -0.115"/>
  </joint>


  <link name="front_right_shoulder_link">
    <visual>
      <geometry>
        <mesh filename="package://spotmicro_cpp_pkg/mesh/LB_RF_shoulder.STL" scale="0.001 0.001 0.001"/>
      </geometry>
      <origin rpy="1.5701 0 3.142" xyz="0.025 -0.01 -0.03825"/>
      <material name="black"/>
    </visual>
    <collision>
      <geometry>
        <box size="0.044 0.038 0.07"/>
      </geometry>
      <origin rpy="0 0 0" xyz="0 0 -0.0095"/>
    </collision>
    <inertial>
      <mass value="0.071"/>
      <inertia ixx="0.000033462" ixy="0" ixz="0" iyy="0.00003153" iyz="-0.000005" izz="0.000021"/>
    </inertial>
  </link>
  <link name="front_right_leg_link_cover">
    <visual>
      <geometry>
        <mesh filename="package://spotmicro_cpp_pkg/mesh/R_arm_cover.STL" scale="0.001 0.001 0.001"/>
      </geometry>
      <origin rpy="0 3.142 0" xyz="0.018 -0.0222 0.025"/>
      <material name="yellow"/>
    </visual>
  </link>
  <link name="front_right_leg_link">
    <visual>
      <geometry>
        <mesh filename="package://spotmicro_cpp_pkg/mesh/R_arm.STL" scale="0.001 0.001 0.001"/>
      </geometry>
      <origin rpy="0 3.142 3.142" xyz="-0.027 0.0275 0.02029"/>
      <material name="black"/>
      <!--        <geometry>
          <box size="0.028 0.036 ${leg_length}"/>
        </geometry>
        <origin rpy="0.0 0.0 0.0" xyz="0.0 0.0 -0.050"/>
        <material name="yellow"/>-->
    </visual>
    <collision>
      <origin rpy="0.0 0.0 0.0" xyz="0.0 0.0 -0.035"/>
      <geometry>
        <box size="0.028 0.036 0.12"/>
      </geometry>
    </collision>
    <inertial>
      <mass value="0.124"/>
      <origin xyz="-0.003 -0.001 -0.041" rpy="0.0 0.0 0.0"/>
      <inertia ixx="0.000396" ixy="0" ixz="0.0000184" iyy="0.000381" iyz="0" izz="0.0000329"/>
    </inertial>
  </link>
  <link name="front_right_foot_link">
    <visual>
      <geometry>
        <mesh filename="package://spotmicro_cpp_pkg/mesh/Right_writs.STL" scale="0.001 0.001 0.001"/>
      </geometry>
      <origin rpy="0 0 -1.571" xyz="-0.014 0.027 -0.131"/>
      <material name="black"/>
    </visual>
    <collision>
      <geometry>
        <box size="0.026 0.020 0.115"/>
      </geometry>
      <origin rpy="0.0 0.0 0.0" xyz="0.0 0.0 -0.050"/>
    </collision>
    <inertial>
      <mass value="0.066"/>
      <origin xyz="-0.0001 -0.0007 -0.029" rpy="0.0 0.0 0.0"/>
      <inertia ixx="0.000161" ixy="0" ixz="0" iyy="0.000164" iyz="-0.0000017" izz="0.000011"/>
    </inertial>
  </link>
  <link name="front_right_toe_link">
    <visual>
      <geometry>
        <mesh filename="package://spotmicro_cpp_pkg/meshes/foot.stl" scale="0.001 0.001 0.001"/>
      </geometry>
      <origin rpy="0 -0.40010 0" xyz="-0.001 -0.0095 0"/>
      <material name="grey"/>
    </visual>
    <collision>
      <geometry>
        <sphere radius="0.02"/>
      </geometry>
      <origin rpy="0 0 0" xyz="0 0 0"/>
      <contact_coefficients mu="1.1"/>
    </collision>
    <inertial>
      <mass value="0.05"/>
      <inertia ixx="1000" ixy="0" ixz="0" iyy="1000" iyz="0" izz="1000"/>
    </inertial>
  </link>

  <joint name="front_right_shoulder" type="revolute">
    <parent link="base_link"/>
    <child link="front_right_shoulder_link"/>
    <axis xyz="1 0 0"/>
    <origin rpy="0 0 0" xyz="-0.09165 0.039 0.009"/>
    <limit effort="1000.0" lower="-0.872" upper="0.698" velocity="0.7"/>
    <dynamics damping="0.0" friction="0.5"/>
  </joint>
  <joint name="front_right_leg" type="revolute">
    <parent link="front_right_shoulder_link"/>
    <child link="front_right_leg_link"/>
    <axis xyz="0 1 0"/>
    <origin rpy="0 0 0" xyz="0 0.0597 -0.01"/>
    <limit effort="1000.0" lower="-1.57" upper="1.57" velocity="0.5"/>
    <dynamics damping="0.0" friction="0.0"/>
  </joint>
  <joint name="front_right_leg_cover_joint" type="fixed">
    <parent link="front_right_leg_link"/>
    <child link="front_right_leg_link_cover"/>
    <origin xyz="0 0 0"/>
  </joint>
  <joint name="front_right_foot" type="revolute">
    <parent link="front_right_leg_link"/>
    <child link="front_right_foot_link"/>
    <axis xyz="0 1 0"/>
    <origin rpy="0 0 0" xyz="-0.01475 0 -0.10699"/>
    <limit effort="1000.0" lower="-0.174" upper="2.268" velocity="0.5"/>
    <dynamics damping="0.0" friction="0.5"/>
  </joint>
  <joint name="front_right_toe" type="fixed">
    <parent link="front_right_foot_link"/>
    <child link="front_right_toe_link"/>
    <origin xyz="0 0 -0.115"/>
  </joint>

  <link name="rear_left_shoulder_link">
    <visual>
      <geometry>
        <mesh filename="package://spotmicro_cpp_pkg/mesh/LB_RF_shoulder.STL" scale="0.001 0.001 0.001"/>
      </geometry>
      <origin rpy="1.5701 0 0" xyz="-0.028 0.01 -0.03825"/>
      <material name="black"/>
    </visual>
    <collision>
      <geometry>
        <box size="0.044 0.038 0.07"/>
      </geometry>
      <origin rpy="0 0 0" xyz="0 0 -0.0095"/>
    </collision>
    <inertial>
      <mass value="0.071"/>
      <inertia ixx="0.0000335" ixy="0" ixz="0" iyy="0.0000315" iyz="0" izz="0.0000207"/>
    </inertial>
  </link>
  <link name="rear_left_leg_link_cover">
    <visual>
      <geometry>
        <mesh filename="package://spotmicro_cpp_pkg/mesh/L_arm_cover.STL" scale="0.001 0.001 0.001"/>
      </geometry>
      <origin rpy="0 3.142 0" xyz="0.016 -0.0287 0.025"/>
      <material name="yellow"/>
    </visual>
  </link>
  <link name="rear_left_leg_link">
    <visual>
      <geometry>
        <mesh filename="package://spotmicro_cpp_pkg/mesh/L_arm.STL" scale="0.001 0.001 0.001"/>
      </geometry>
      <origin rpy="0 3.142 3.142" xyz="-0.02825 0.036 0.13809"/>
      <material name="black"/>
      <!--        <geometry>
          <box size="0.028 0.036 ${leg_length}"/>
        </geometry>
        <origin rpy="0.0 0.0 0.0" xyz="0.0 0.0 -0.050"/>
        <material name="yellow"/>-->
    </visual>
    <collision>
      <origin rpy="0.0 0.0 0.0" xyz="0.0 0.0 -0.035"/>
      <geometry>
        <box size="0.028 0.036 0.12"/>
      </geometry>
    </collision>
    <inertial>
      <mass value="0.124"/>
      <origin xyz="-0.003 0.001 -0.0407" rpy="0.0 0.0 0.0"/>
      <inertia ixx="0.000396" ixy="0" ixz="0.0000184" iyy="0.000038" iyz="-0.000003" izz="0.0000329"/>
    </inertial>
  </link>
  <link name="rear_left_foot_link">
    <visual>
      <geometry>
        <mesh filename="package://spotmicro_cpp_pkg/mesh/Left_writs.STL" scale="0.001 0.001 0.001"/>
      </geometry>
      <origin rpy="0 0 -1.571" xyz="-0.016 0.0277 -0.2048"/>
      <material name="black"/>
    </visual>
    <collision>
      <geometry>
        <box size="0.026 0.020 0.115"/>
      </geometry>
      <origin rpy="0.0 0.0 0.0" xyz="0.0 0.0 -0.050"/>
    </collision>
    <inertial>
      <mass value="0.0657"/>
      <origin xyz="0.00066 0.00011 -0.0292" rpy="0.0 0.0 0.0"/>
      <inertia ixx="0.000164" ixy="0" ixz="0" iyy="0.000161" iyz="0" izz="0.0000107"/>
    </inertial>
  </link>
  <link name="rear_left_toe_link">
    <visual>
      <geometry>
        <mesh filename="package://spotmicro_cpp_pkg/meshes/foot.stl" scale="0.001 0.001 0.001"/>
      </geometry>
      <origin rpy="0 -0.40010 0" xyz="-0.001 -0.0105 0"/>
      <material name="grey"/>
    </visual>
    <collision>
      <geometry>
        <sphere radius="0.02"/>
      </geometry>
      <origin rpy="0 0 0" xyz="0 0 0"/>
      <contact_coefficients mu="1.1"/>
    </collision>
    <inertial>
      <mass value="0.05"/>
      <inertia ixx="1000" ixy="0" ixz="0" iyy="1000" iyz="0" izz="1000"/>
    </inertial>
  </link>

  <joint name="rear_left_shoulder" type="revolute">
    <parent link="base_link"/>
    <child link="rear_left_shoulder_link"/>
    <axis xyz="1 0 0"/>
    <origin rpy="0 0 0" xyz="0.09165 -0.039 0.009"/>
    <limit effort="1000.0" lower="-0.872" upper="0.698" velocity="0.7"/>
    <dynamics damping="0.0" friction="0.5"/>
  </joint>
  <joint name="rear_left_leg" type="revolute">
    <parent link="rear_left_shoulder_link"/>
    <child link="rear_left_leg_link"/>
    <axis xyz="0 1 0"/>
    <origin rpy="0 0 0" xyz="0 -0.0597 -0.01"/>
    <limit effort="1000.0" lower="-1.57" upper="1.57" velocity="0.5"/>
    <dynamics damping="0.0" friction="0.0"/>
  </joint>
  <joint name="rear_left_leg_cover_joint" type="fixed">
    <parent link="rear_left_leg_link"/>
    <child link="rear_left_leg_link_cover"/>
    <origin xyz="0 0 0"/>
  </joint>
  <joint name="rear_left_foot" type="revolute">
    <parent link="rear_left_leg_link"/>
    <child link="rear_left_foot_link"/>
    <axis xyz="0 1 0"/>
    <origin rpy="0 0 0" xyz="-0.01475 0 -0.10699"/>
    <limit effort="1000.0" lower="-0.174" upper="2.268" velocity="0.5"/>
    <dynamics damping="0.0" friction="0.5"/>
  </joint>
  <joint name="rear_left_toe" type="fixed">
    <parent link="rear_left_foot_link"/>
    <child link="rear_left_toe_link"/>
    <origin xyz="0 0 -0.115"/>
  </joint>


  <link name="rear_right_shoulder_link">
    <visual>
      <geometry>
        <mesh filename="package://spotmicro_cpp_pkg/mesh/LF_RB_shoulder.STL" scale="0.001 0.001 0.001"/>
      </geometry>
      <origin rpy="1.5701 0 3.142" xyz="0.027 -0.0102 -0.03825"/>
      <material name="black"/>
    </visual>
    <collision>
      <geometry>
        <box size="0.044 0.038 0.07"/>
      </geometry>
      <origin rpy="0 0 0" xyz="0 0 -0.0095"/>
    </collision>
    <inertial>
      <mass value="0.10"/>
      <inertia ixx="100" ixy="0" ixz="0" iyy="100" iyz="0" izz="100"/>
    </inertial>
  </link>
  <link name="rear_right_leg_link_cover">
    <visual>
      <geometry>
        <mesh filename="package://spotmicro_cpp_pkg/mesh/R_arm_cover.STL" scale="0.001 0.001 0.001"/>
      </geometry>
      <origin rpy="0 3.142 0" xyz="0.016 -0.0222 0.025"/>
      <material name="yellow"/>
    </visual>
  </link>
  <link name="rear_right_leg_link">
    <visual>
      <geometry>
        <mesh filename="package://spotmicro_cpp_pkg/mesh/R_arm.STL" scale="0.001 0.001 0.001"/>
      </geometry>
      <origin rpy="0 3.142 3.142" xyz="-0.029 0.0275 0.02029"/>
      <material name="black"/>
      <!--        <geometry>
          <box size="0.028 0.036 ${leg_length}"/>
        </geometry>
        <origin rpy="0.0 0.0 0.0" xyz="0.0 0.0 -0.050"/>
        <material name="yellow"/>-->
    </visual>
    <collision>
      <origin rpy="0.0 0.0 0.0" xyz="0.0 0.0 -0.035"/>
      <geometry>
        <box size="0.028 0.036 0.12"/>
      </geometry>
    </collision>
    <inertial>
      <mass value="0.124"/>
      <origin xyz="-0.003 -0.001 -0.041" rpy="0.0 0.0 0.0"/>
      <inertia ixx="0.000396" ixy="0" ixz="0.0000184" iyy="0.000381" iyz="0" izz="0.0000329"/>
    </inertial>
  </link>
  <link name="rear_right_foot_link">
    <visual>
      <geometry>
        <mesh filename="package://spotmicro_cpp_pkg/mesh/Right_writs.STL" scale="0.001 0.001 0.001"/>
      </geometry>
      <origin rpy="0 0 -1.571" xyz="-0.014 0.027 -0.131"/>
      <material name="black"/>
    </visual>
    <collision>
      <geometry>
        <box size="0.026 0.020 0.115"/>
      </geometry>
      <origin rpy="0.0 0.0 0.0" xyz="0.0 0.0 -0.050"/>
    </collision>
    <inertial>
      <mass value="0.066"/>
      <origin xyz="-0.0001 -0.0007 -0.029" rpy="0.0 0.0 0.0"/>
      <inertia ixx="0.000161" ixy="0" ixz="0" iyy="0.000164" iyz="-0.0000017" izz="0.000011"/>
    </inertial>
  </link>
  <link name="rear_right_toe_link">
    <visual>
      <geometry>
        <mesh filename="package://spotmicro_cpp_pkg/meshes/foot.stl" scale="0.001 0.001 0.001"/>
      </geometry>
      <origin rpy="0 -0.40010 0" xyz="0 -0.01 0"/>
      <material name="grey"/>
    </visual>
    <collision>
      <geometry>
        <sphere radius="0.02"/>
      </geometry>
      <origin rpy="0 0 0" xyz="0 0 0"/>
      <contact_coefficients mu="1.1"/>
    </collision>
    <inertial>
      <mass value="0.05"/>
      <inertia ixx="1000" ixy="0" ixz="0" iyy="1000" iyz="0" izz="1000"/>
    </inertial>
  </link>

  <joint name="rear_right_shoulder" type="revolute">
    <parent link="base_link"/>
    <child link="rear_right_shoulder_link"/>
    <axis xyz="1 0 0"/>
    <origin rpy="0 0 0" xyz="0.09165 0.039 0.009"/>
    <limit effort="1000.0" lower="-0.872" upper="0.698" velocity="0.7"/>
    <dynamics damping="0.0" friction="0.5"/>
  </joint>
  <joint name="rear_right_leg" type="revolute">
    <parent link="rear_right_shoulder_link"/>
    <child link="rear_right_leg_link"/>
    <axis xyz="0 1 0"/>
    <origin rpy="0 0 0" xyz="0 0.0597 -0.01"/>
    <limit effort="1000.0" lower="-1.57" upper="1.57" velocity="0.5"/>
    <dynamics damping="0.0" friction="0.0"/>
  </joint>
  <joint name="rear_right_leg_cover_joint" type="fixed">
    <parent link="rear_right_leg_link"/>
    <child link="rear_right_leg_link_cover"/>
    <origin xyz="0 0 0"/>
  </joint>
  <joint name="rear_right_foot" type="revolute">
    <parent link="rear_right_leg_link"/>
    <child link="rear_right_foot_link"/>
    <axis xyz="0 1 0"/>
    <origin rpy="0 0 0" xyz="-0.01475 0 -0.10699"/>
    <limit effort="1000.0" lower="-0.174" upper="2.268" velocity="0.5"/>
    <dynamics damping="0.0" friction="0.5"/>
  </joint>
  <joint name="rear_right_toe" type="fixed">
    <parent link="rear_right_foot_link"/>
    <child link="rear_right_toe_link"/>
    <origin xyz="0 0 -0.115"/>
  </joint>
</robot>
